Traceback (most recent call last):
  File "C:\Users\Rameez Raja\Downloads\mlops-capstone\.venv\Lib\site-packages\pandas\core\indexes\base.py", line 3812, in get_loc
    return self._engine.get_loc(casted_key)
           ~~~~~~~~~~~~~~~~~~~~^^^^^^^^^^^^
  File "pandas/_libs/index.pyx", line 167, in pandas._libs.index.IndexEngine.get_loc
  File "pandas/_libs/index.pyx", line 196, in pandas._libs.index.IndexEngine.get_loc
  File "pandas/_libs/hashtable_class_helper.pxi", line 2606, in pandas._libs.hashtable.Int64HashTable.get_item
  File "pandas/_libs/hashtable_class_helper.pxi", line 2630, in pandas._libs.hashtable.Int64HashTable.get_item
KeyError: 0

The above exception was the direct cause of the following exception:

Traceback (most recent call last):
  File "C:\Users\Rameez Raja\Downloads\mlops-capstone\src\train.py", line 74, in <module>
    main()
    ~~~~^^
  File "C:\Users\Rameez Raja\Downloads\mlops-capstone\src\train.py", line 61, in main
    wandb.log({"confusion_matrix": wandb.plot.confusion_matrix(
                                   ~~~~~~~~~~~~~~~~~~~~~~~~~~~^
        y_true=y_test, preds=y_pred_test, class_names=["Not Survived", "Survived"]
        ^^^^^^^^^^^^^^^^^^^^^^^^^^^^^^^^^^^^^^^^^^^^^^^^^^^^^^^^^^^^^^^^^^^^^^^^^^
    )})
    ^
  File "C:\Users\Rameez Raja\Downloads\mlops-capstone\.venv\Lib\site-packages\wandb\plot\confusion_matrix.py", line 164, in confusion_matrix
    counts[class_mapping[y_true[i]], class_mapping[preds[i]]] += 1
                         ~~~~~~^^^
  File "C:\Users\Rameez Raja\Downloads\mlops-capstone\.venv\Lib\site-packages\pandas\core\series.py", line 1133, in __getitem__
    return self._get_value(key)
           ~~~~~~~~~~~~~~~^^^^^
  File "C:\Users\Rameez Raja\Downloads\mlops-capstone\.venv\Lib\site-packages\pandas\core\series.py", line 1249, in _get_value
    loc = self.index.get_loc(label)
  File "C:\Users\Rameez Raja\Downloads\mlops-capstone\.venv\Lib\site-packages\pandas\core\indexes\base.py", line 3819, in get_loc
    raise KeyError(key) from err
KeyError: 0
